Workbook

Sheet MobileCall
B1: Total_dose_call | D1: Total_dose_phone | F1: Total_dose_headphone_BT | H1: Total_dose_phone_BT | J1: Duration | K1: connection mode_transmitter_weighted_m_SAR | M1: aggregated_BT_mSAR | Q1: transmitter_weighted_mSAR | AQ1: Positions | AW1: transmitter_position_weighted_SAR | BI1: SAR_wifi2 | BU1: SAR_wifi5 | CG1: Connectivity_mode | CJ1: Output power | CT1: network_technology_native | CX1: network_technology_data_call | DB1: wifi_technology_call | DD1: power_native call | EF1: power_data_call | FB1: power_wifi_call | FD1: Power_BT_call | FE1: duty_cycle | FP1: frequency contribution | FW1: SAR_native_call | IA1: SAR_earware_BT_wifi2 | IC1: conectivity_mode
B2: mJ/kg/day | D2: mJ/kg/day | F2: mJ/kg/day | H2: mJ/kg/day | J2: second | M2: headphone | O2: phone | Q2: native call | AA2: data call | AK2: wifi call | AQ2: proportion | AW2: 2G | AY2: 3G | BA2: 4G | BC2: 5G | BE2: wifi2 | BG2: wifi5 | BI2: W/kg/W | BU2: W/kg/W | CG2: proportion | CJ2: Native call | CN2: data call | CR2: wifi | CT2: proportion | CX2: proportion | DB2: proportion | DD2: mW | EF2: mW | FB2: mW | FD2: mW | FE2: 2G | FG2: 3G | FI2: 4G | FK2: 5G | FM2: wifi2 | FN2: wifi5 | FO2: BT | FP2: proportion | FW2: brain | GY2: WB | IA2: W/kg/W | IC2: proportion
A3: source | B3: brain | C3: WB | D3: brain | E3: WB | F3: brain | G3: WB | H3: brain | I3: WB | K3: Total | M3: brain | N3: wb | O3: brain | P3: wb | Q3: brain | V3: wb | AA3: brain | AF3: wb | AK3: brain | AN3: wb | AQ3: ear | AR3: headphone | AS3: headset_position of phone during call over heaadphone | AV3: speaker(front of mouth) | AW3: brain | AX3: wb | AY3: brain | AZ3: wb | BA3: brain | BB3: wb | BC3: brain | BD3: wb | BE3: brain | BF3: wb | BG3: brain | BH3: wb | BI3: brain | BO3: WB | BU3: brain | CA3: WB | CG3: network | CH3: data | CI3: wifi | CJ3: 2G | CK3: 3G | CL3: 4G | CM3: 5G | CN3: 2G | CO3: 3G | CP3: 4G | CQ3: 5G | CR3: wifi2 | CS3: wifi5 | CT3: 2G | CU3: 3G | CV3: 4G | CW3: 5G | CX3: 2G | CY3: 3G | CZ3: 4G | DA3: 5G | DB3: wifi2 | DC3: wifi5 | DD3: 2G | DK3: 3G | DR3: 4G | DY3: 5G | EF3: 2G | EG3: 3G | EN3: 4G | EU3: 5G | FB3: wifi2 | FC3: wifi5 | FE3: native_call | FF3: data_call | FG3: native_call | FH3: data_call | FI3: native_call | FJ3: data_call | FK3: native_call | FL3: data_call | FM3: call | FN3: call | FO3: call | FP3: 700 | FQ3: 800 | FR3: 900 | FS3: 1800 | FT3: 2100 | FU3: 2600 | FV3: 3500 | FW3: to_ear | GD3: speaker(front of mouth) | GK3: pocket | GR3: front_of_face | GY3: to_ear | HF3: speaker(front of mouth) | HM3: pocket | HT3: front_of_face | IA3: brain | IB3: WB | IC3: total | IE3: home | IG3: school | II3: commuting | IK3: outdoor | IM3: Reference | IN3: Remarks
A4: variable | K4: brain | L4: wb | Q4: Total | R4: 2G | S4: 3G | T4: 4G | U4: 5G | V4: total | W4: 2G | X4: 3G | Y4: 4G | Z4: 5G | AA4: total | AB4: 2G | AC4: 3G | AD4: 4G | AE4: 5G | AF4: Total | AG4: 2G | AH4: 3G | AI4: 4G | AJ4: 5G | AK4: total | AL4: wifi2 | AM4: wifi5 | AN4: total | AO4: wifi2 | AP4: wifi5 | AS4: front_of face | AT4: pocket | AU4: far | BI4: ear | BJ4: agregated_phone_position_(during headset use) | BK4: front_of face | BL4: pocket | BM4: far | BN4: speaker(front of mouth) | BO4: ear | BP4: agregated_phone_position_(during headset use) | BQ4: front_of face | BR4: pocket | BS4: far | BT4: speaker(front of mouth) | BU4: ear | BV4: agregated_phone_position_(during headset use) | BW4: front_of face | BX4: pocket | BY4: far | BZ4: speaker(front of mouth) | CA4: ear | CB4: agregated_phone_position_(during headset use) | CC4: front_of face | CD4: pocket | CE4: far | CF4: speaker(front of mouth)(FoF) | DD4: urban_indoor | DE4: urban_outdoor | DF4: suburban_indoor | DG4: suburban_outdoor | DH4: rural_indoor | DI4: rural_outdoor | DJ4: traveling | DK4: urban_indoor | DL4: urban_outdoor | DM4: suburban_indoor | DN4: suburban_outdoor | DO4: rural_indoor | DP4: rural_outdoor | DQ4: traveling | DR4: urban_indoor | DS4: urban_outdoor | DT4: suburban_indoor | DU4: suburban_outdoor | DV4: rural_indoor | DW4: rural_outdoor | DX4: traveling | DY4: urban_indoor | DZ4: urban_outdoor | EA4: suburban_indoor | EB4: suburban_outdoor | EC4: rural_indoor | ED4: rural_outdoor | EE4: traveling | EG4: urban_indoor | EH4: urban_outdoor | EI4: suburban_indoor | EJ4: suburban_outdoor | EK4: rural_indoor | EL4: rural_outdoor | EM4: traveling | EN4: urban_indoor | EO4: urban_outdoor | EP4: suburban_indoor | EQ4: suburban_outdoor | ER4: rural_indoor | ES4: rural_outdoor | ET4: traveling | EU4: urban_indoor | EV4: urban_outdoor | EW4: suburban_indoor | EX4: suburban_outdoor | EY4: rural_indoor | EZ4: rural_outdoor | FA4: traveling | FW4: 700 | FX4: 800 | FY4: 900 | FZ4: 1800 | GA4: 2100 | GB4: 2600 | GC4: 3500 | GD4: 700 | GE4: 800 | GF4: 900 | GG4: 1800 | GH4: 2100 | GI4: 2600 | GJ4: 3500 | GK4: 700 | GL4: 800 | GM4: 900 | GN4: 1800 | GO4: 2100 | GP4: 2600 | GQ4: 3500 | GR4: 700 | GS4: 800 | GT4: 900 | GU4: 1800 | GV4: 2100 | GW4: 2600 | GX4: 3500 | GY4: 700 | GZ4: 800 | HA4: 900 | HB4: 1800 | HC4: 2100 | HD4: 2600 | HE4: 3500 | HF4: 700 | HG4: 800 | HH4: 900 | HI4: 1800 | HJ4: 2100 | HK4: 2600 | HL4: 3500 | HM4: 700 | HN4: 800 | HO4: 900 | HP4: 1800 | HQ4: 2100 | HR4: 2600 | HS4: 3500 | HT4: 700 | HU4: 800 | HV4: 900 | HW4: 1800 | HX4: 2100 | HY4: 2600 | HZ4: 3500 | IC4: data | ID4: wifi | IE4: data | IF4: wifi | IG4: data | IH4: wifi | II4: data | IJ4: wifi | IK4: data | IL4: wifi
A5: Summary | B5: =D5+F5+H5 -> 322.77372 | C5: =E5+G5+I5 -> 66.647262 | D5: =J5*K5 -> 320.49514 | E5: =J5*L5 -> 64.930428 | F5: =J5*M5*2 -> 2.2575912 | G5: =J5*N5*2 -> 1.5829483 | H5: =J5*O5 -> 0.02099412 | I5: =J5*P5 -> 0.13388614 | J5: =[1]Sheet1!$B$12 -> 1533.3532 | K5: =CG5*Q5+CH5*AA5+CI5*AK5 -> 0.20901586 | L5: =CG5*V5+CH5*AF5+CI5*AN5 -> 0.042345382 | M5: =AR5*IA5*FD5*FO5 -> 0.00073616151 | N5: =AR5*IB5*FD5*FO5 -> 0.0005161721 | O5: =AR5*BJ5*FD5*FO5 -> 1.369164e-05 | P5: =AR5*BP5*FD5*FO5 -> 8.7315918e-05 | Q5: =R5*CT5+S5*CU5+T5*CV5+U5*CW5 -> 0.27543147 | R5: =AW5*CJ5 -> 5.5454447 | S5: =AY5*CK5 -> 0.067507437 | T5: =BA5*CL5 -> 0.23862487 | U5: =BC5*CM5 -> 0 | V5: =W5*CT5+X5*CU5+Y5*CV5+Z5*CW5 -> 0.050371323 | W5: =AX5*CJ5 -> 0.97175652 | X5: =AZ5*CK5 -> 0.01224002 | Y5: =BB5*CL5 -> 0.043968153 | Z5: =BD5*CM5 -> 0 | AA5: =AB5*CX5+AC5*CY5+AD5*CZ5+AE5*DA5 -> 0.1046509 | AB5: =AW5*CN5 -> 0 | AC5: =AY5*CO5 -> 0.03821353 | AD5: =BA5*CP5 -> 0.15412491 | AE5: =BC5*CQ5 -> 0.0070068933 | AF5: =AG5*CX5+AH5*CY5+AI5*CZ5+AJ5*DA5 -> 0.023521457 | AG5: =AX5*CN5 -> 0 | AH5: =AZ5*CO5 -> 0.0069286346 | AI5: =BB5*CP5 -> 0.028398497 | AJ5: =BD5*CQ5 -> 0.014440923 | AK5: =AL5*DB5+AM5*DC5 -> 0.022414125 | AL5: =BE5*CR5 -> 0.034377935 | AM5: =BG5*CS5 -> 0.0058926728 | AN5: =AO5*DB5+AP5*DC5 -> 0.023678651 | AO5: =BF5*CR5 -> 0.015339508 | AP5: =BH5*CS5 -> 0.035194611 | AQ5: =[1]Sheet1!$B$5 -> 0.44776904 | AR5: =[1]Sheet1!$B$6 -> 0.22948502 | AS5: 0.333 | AT5: 0.333 | AU5: 0.333 | AV5: =1-(AQ5+AR5) -> 0.32274594 | AW5: =$AQ$5*S36+$AR$5*T36+$AV$5*X36 -> 0.038915611 | AX5: =$AQ$5*Y36+$AR$5*Z36+$AV$5*AD36 -> 0.0068193806 | AY5: =$AQ$5*S37+$AR$5*T37+$AV$5*X37 -> 0.036596764 | AZ5: =$AQ$5*Y37+$AR$5*Z37+$AV$5*AD37 -> 0.0066354928 | BA5: =$AQ$5*S38+$AR$5*T38+$AV$5*X38 -> 0.035978107 | BB5: =$AQ$5*Y38+$AR$5*Z38+$AV$5*AD38 -> 0.0066291954 | BC5: =$AQ$5*S39+$AR$5*T39+$AV$5*X39 -> 0.0028402645 | BD5: =$AQ$5*Y39+$AR$5*Z39+$AV$5*AD39 -> 0.00585367 | BE5: =$AQ$5*BI5+$AR$5*BJ5+$AV$5*BN5 -> 0.012555857 | BF5: =$AQ$5*BO5+$AR$5*BP5+$AV$5*BT5 -> 0.0056024498 | BG5: =$AQ$5*BU5+$AR$5*BV5+$AV$5*BZ5 -> 0.00059763416 | BH5: =$AQ$5*CA5+$AR$5*CB5+$AV$5*CF5 -> 0.0035694332 | BI5: =[4]Sheet1!$I$7 -> 0.026727749 | BJ5: =AS5*BK5+AT5*BL5+AU5*BM5 -> 0.00037289035 | BK5: =[4]Sheet1!$I$27 -> 0.0011194632 | BL5: =[4]Sheet1!$I$37 -> 3.2767949e-07 | BM5: 0 | BN5: =[4]Sheet1!$I$17 -> 0.0015567211 | BO5: =[5]Sheet1!$H$7 -> 0.010022773 | BP5: =AS5*BQ5+AT5*BR5+AU5*BS5 -> 0.0023780397 | BQ5: =[5]Sheet1!$H$27 -> 0.00086311725 | BR5: =[5]Sheet1!$H$37 -> 0.0062781431 | BS5: 0 | BT5: =[5]Sheet1!$H$17 -> 0.0017624951 | BU5: =[4]Sheet1!$I$10 -> 0.0010403714 | BV5: =AS5*BW5+AT5*BX5+AU5*BY5 -> 0.00010658385 | BW5: =[4]Sheet1!$I$30 -> 0.00032007162 | BX5: =[4]Sheet1!$I$40 -> 1.3703765e-11 | BY5: 0 | BZ5: =[4]Sheet1!$I$20 -> 0.00033254851 | CA5: =[5]Sheet1!$H$10 -> 0.0065385221 | CB5: =AS5*CC5+AT5*CD5+AU5*CE5 -> 0.0010079979 | CC5: =[5]Sheet1!$H$30 -> 0.00055363292 | CD5: =[5]Sheet1!$H$40 -> 0.0024733878 | CE5: 0 | CF5: =[5]Sheet1!$H$20 -> 0.00127148 | CG5: 0.7 | CH5: =IC5*(1-CG5) -> 0.11539355 | CI5: =ID5*(1-CG5) -> 0.18460645 | CJ5: =((Farfield!$N$5+Farfield!$P$5)*DF5+Farfield!$O$5*DG5+Farfield!$Q$5*DJ5)*FE5 -> 142.49923 | CK5: =((Farfield!$N$5+Farfield!$P$5)*DM5+Farfield!$O$5*DN5+Farfield!$Q$5*DQ5)*FG5 -> 1.8446286 | CL5: =((Farfield!$N$5+Farfield!$P$5)*DT5+Farfield!$O$5*DU5+Farfield!$Q$5*DX5)*FI5 -> 6.6325021 | CM5: =((Farfield!$N$5+Farfield!$P$5)*EA5+Farfield!$O$5*EB5+Farfield!$Q$5*EE5)*FK5 -> 0 | CN5: 0 | CO5: =((Farfield!$N$5+Farfield!$P$5)*EI5+Farfield!$O$5*EJ5+Farfield!$Q$5*EM5)*FH5 -> 1.0441778 | CP5: =((Farfield!$N$5+Farfield!$P$5)*EP5+Farfield!$O$5*EQ5+Farfield!$Q$5*ET5)*FJ5 -> 4.2838527 | CQ5: =((Farfield!$N$5+Farfield!$P$5)*EW5+Farfield!$O$5*EX5+Farfield!$Q$5*FA5)*FL5 -> 2.4669862 | CR5: =FB5*FM5 -> 2.738 | CS5: =FN5*FC5 -> 9.86 | CT5: =CT13 -> 0.0075 | CU5: =CU13 -> 0.0175 | CV5: =AVERAGE(CV23:CV24) -> 0.975 | CW5: 0 | CX5: 0 | CY5: =CU5 -> 0.0175 | CZ5: =CV13 -> 0.66 | DA5: =CT13+CW13 -> 0.3225 | DB5: 0.58 | DC5: 0.42 | DD5: =AVERAGE(DD21,DD61) -> 374.86821 | DE5: =AVERAGE(DE21,DE60) -> 173.80504 | DF5: =AVERAGE(DF21,DF61) -> 1281.5155 | DG5: =AVERAGE(DG21,DG60) -> 383.89741 | DH5: =AVERAGE(DH21,DH61) -> 1371.2333 | DI5: =AVERAGE(DI21,DI60) -> 433.89741 | DJ5: =DG5 -> 383.89741 | DK5: =AVERAGE(DK20:DK63) -> 0.97 | DL5: =AVERAGE(DL20:DL62) -> 0.21837582 | DM5: 2.03 | DN5: =AVERAGE(DN21:DN44) -> 0.63297821 | DO5: =AVERAGE(DO21:DO44) -> 6.2 | DP5: =DP21 -> 2.644793 | DQ5: =DN5 -> 0.63297821 | DR5: 140.5 | DS5: 94.3 | DT5: =AVERAGE(DR5,DV5) -> 159.3 | DU5: =AVERAGE(DS5,DW5) -> 109.75 | DV5: 178.1 | DW5: 125.2 | DX5: =DU5 -> 109.75 | DY5: 0 | DZ5: 0 | EA5: =AVERAGE(DY5,EC5) -> 0 | EB5: =AVERAGE(DZ5,ED5) -> 0 | EC5: 0 | ED5: 0 | EE5: 0 | EF5: 0 | EG5: =AVERAGE(EG20:EG31) -> 0.605 | EH5: =EH30 -> 0.25808061 | EI5: 2.04 | EJ5: 0.87 | EK5: 6.28 | EL5: 2.68 | EM5: =EJ5 -> 0.87 | EN5: 64.105638 | EO5: 54.479069 | EP5: =AVERAGE(EN5,ER5) -> 77.898518 | EQ5: =AVERAGE(EO5,ES5) -> 68.405662 | ER5: 91.691398 | ES5: 82.332255 | ET5: 74.3 | EU5: 46.35 | EV5: 36.92 | EW5: 49.13 | EX5: 40.045 | EY5: 51.91 | EZ5: 43.17 | FA5: 31.52 | FB5: 100 | FC5: 200 | FD5: 1 | FE5: 0.12 | FF5: 0 | FG5: =AVERAGE(FG30:FG33) -> 0.979275 | FH5: =AVERAGE(FH30:FH32) -> 0.54456667 | FI5: =AVERAGE(FI14:FI15) -> 0.0430375 | FJ5: =AVERAGE(FJ14:FJ15) -> 0.0556125 | FK5: 0 | FL5: =AVERAGE(FL14:FL15) -> 0.0514 | FM5: =AVERAGE(FM43:FM50) -> 0.02738 | FN5: =AVERAGE(FN52:FN55) -> 0.0493 | FO5: 0.16 | FW5: =[4]Sheet1!$I$2 -> 0.13006405 | FX5: =[4]Sheet1!$I$3 -> 0.12393633 | FY5: =[4]Sheet1!$I$4 -> 0.11559835 | FZ5: =[4]Sheet1!$I$5 -> 0.046356407 | GA5: =[4]Sheet1!$I$6 -> 0.036757199 | GB5: =[4]Sheet1!$I$8 -> 0.022514603 | GC5: =[4]Sheet1!$I$9 -> 0.0055389929 | GD5: =[4]Sheet1!$I$12 -> 0.011281702 | GE5: =[4]Sheet1!$I$13 -> 0.011873286 | GF5: =[4]Sheet1!$I$14 -> 0.011306646 | GG5: =[4]Sheet1!$I$15 -> 0.0032107719 | GH5: =[4]Sheet1!$I$16 -> 0.0022888349 | GI5: =[4]Sheet1!$I$18 -> 0.0014547261 | GJ5: =[4]Sheet1!$I$19 -> 0.00095661199 | GK5: =[4]Sheet1!$I$32 -> 1.7412275e-05 | GL5: =[4]Sheet1!$I$33 -> 1.0178719e-05 | GM5: =[4]Sheet1!$I$34 -> 6.4273436e-06 | GN5: =[4]Sheet1!$I$35 -> 8.6760009e-07 | GO5: =[4]Sheet1!$I$36 -> 6.6947377e-07 | GP5: =[4]Sheet1!$I$38 -> 3.2542265e-07 | GQ5: =[4]Sheet1!$I$39 -> 2.3122642e-07 | GR5: =[4]Sheet1!$I$22 -> 0.0052001321 | GS5: =[4]Sheet1!$I$23 -> 0.0059920117 | GT5: =[4]Sheet1!$I$24 -> 0.0061323189 | GU5: =[4]Sheet1!$I$25 -> 0.002071216 | GV5: =[4]Sheet1!$I$26 -> 0.0015229456 | GW5: =[4]Sheet1!$I$28 -> 0.0010649384 | GX5: =[4]Sheet1!$I$29 -> 0.00067149569 | GY5: =[5]Sheet1!$H$2 -> 0.01235998 | GZ5: =[5]Sheet1!$H$3 -> 0.012324044 | HA5: =[5]Sheet1!$H$4 -> 0.012304222 | HB5: =[5]Sheet1!$H$5 -> 0.011088893 | HC5: =[5]Sheet1!$H$6 -> 0.01054371 | HD5: =[5]Sheet1!$H$8 -> 0.009871173 | HE5: =[5]Sheet1!$H$9 -> 0.0093079113 | HF5: =[5]Sheet1!$H$12 -> 0.0025625463 | HG5: =[5]Sheet1!$H$13 -> 0.002600383 | HH5: =[5]Sheet1!$H$14 -> 0.0025273974 | HI5: =[5]Sheet1!$H$15 -> 0.0020888569 | HJ5: =[5]Sheet1!$H$16 -> 0.0019220254 | HK5: =[5]Sheet1!$H$18 -> 0.0017111707 | HL5: =[5]Sheet1!$H$19 -> 0.0015678084 | HM5: =[5]Sheet1!$H$32 -> 0.012145422 | HN5: =[5]Sheet1!$H$33 -> 0.011758565 | HO5: =[5]Sheet1!$H$34 -> 0.011416986 | HP5: =[5]Sheet1!$H$35 -> 0.0083457105 | HQ5: =[5]Sheet1!$H$36 -> 0.0074539133 | HR5: =[5]Sheet1!$H$38 -> 0.0058203138 | HS5: =[5]Sheet1!$H$39 -> 0.0040844685 | HT5: =[5]Sheet1!$H$22 -> 0.001114629 | HU5: =[5]Sheet1!$H$23 -> 0.0011643615 | HV5: =[5]Sheet1!$H$24 -> 0.0011924328 | HW5: =[5]Sheet1!$H$25 -> 0.00095279762 | HX5: =[5]Sheet1!$H$26 -> 0.00093100545 | HY5: =[5]Sheet1!$H$28 -> 0.00084724207 | HZ5: =[5]Sheet1!$H$29 -> 0.0007262761 | IA5: =[4]Sheet1!$J$62 -> 0.02004928 | IB5: =[5]Sheet1!$I$62 -> 0.014057892 | IC5: =IE5*Farfield!N5+IG5*Farfield!P5+II5*Farfield!Q5+IK5*Farfield!O5 -> 0.38464516 | ID5: =IF5*Farfield!N5+IH5*Farfield!P5+IJ5*Farfield!Q5+IL5*Farfield!O5 -> 0.61535484 | IE5: =1-IF5 -> 0.26213168 | IF5: =[1]Sheet1!$B$9 -> 0.73786832 | IG5: =1-IH5 -> 0.51078185 | IH5: =[1]Sheet1!$B$10 -> 0.48921815 | II5: =1-IJ5 -> 0.69282794 | IJ5: =[1]Sheet1!$B$11 -> 0.30717206 | IK5: 1 | IL5: 0
A6: user_inputs | DF6: default for indoor (work and home) | DG6: default for outdoor | DM6: default for indoor (work and home) | DN6: default for outdoor | DT6: default for indoor (work and home) | DU6: default for outdoor | EI6: default for indoor (work and home) | EJ6: default for outdoor | EP6: default for indoor (work and home) | EQ6: default for outdoor
A7: single data | J7: 6 | IM7: Eeftens M, Shen C, Sönksen J, Schmutz C, van Wel L, Liorni I, et al. Modelling of daily radiofrequency electromagnetic field dose for a prospective adolescent cohort. Environment International. 2023;172:107737.
J8: 0.7 | FW8: Adriana measurment_2023_EU | IM8: Birks LE, van Wel L, Liorni I, Pierotti L, Guxens M, Huss A, et al. Radiofrequency electromagnetic fields from mobile communication: Description of modeled dose in brain regions and the body in European children and adolescents. Environmental research. 2021;193:110505
J9: 10.6 | FO9: new value | IM9: Foerster M, Thielens A, Joseph W, Eeftens M, Röösli M. A Prospective Cohort Study of Adolescents' Memory Performance and Individual Brain Dose of Microwave Radiation from Wireless Communication. Environ Health Perspect. 2018;126(7):077007.
J10: 11 | DJ10: same as suburban outdoor | DQ10: same as suburban outdoor | DX10: same as suburban outdoor | IM10: van Wel L, Liorni I, Huss A, Thielens A, Wiart J, Joseph W, et al. Radio-frequency electromagnetic field exposure and contribution of sources in the general population: an organ-specific integrative exposure assessment. J Expo Sci Environ Epidemiol. 2021;31(6):999-1007.
AQ11: 0.66 | AR11: 0.17 | AV11: 0.17 | FI11: new values | FJ11: new values | FK11: new values | FL11: new values | IM11: Goedhart G, van Wel L, Langer CE, de Llobet Viladoms P, Wiart J, Hours M, et al. Recall of mobile phone usage and laterality in young people: The multinational Mobi-Expo study. Environmental Research. 2018;165:150-7. | IN11: MOBI-Kids study (2012 to 2014)--> “Participants reported that in ≥50% of call time they use of headset (wired) 17.1% or speaker (17.2%) mode use (high frequent use was not reported for Bluetooth headset)
CG12: 0.7 | CH12: new calculation | CI12: new calculation | DB12: new numbers | DC12: new numbers | DD12: Adrian_GOLIAT_2023_EU | FP12: Frequency contribution in different technology | IM12: INEGI. Distribution of Smartphone Users in Mexico from 2016 to 2019, by Internet Connection Type. 2020. | IN12: the proportion of native and internet calls are estimation. However, 27% and 3% are based on this fact people 91% of time we use mobile data and 9% Wi-Fi (so, 91%*0.30=27%) (4). This reference mentioned, “In 2019, approximately 90.6 percent of smartphone users in Mexico had a mobile internet connection, while 9.4 percent accessed the web only via Wi-Fi.”
CG13: 0.7 | CT13: =AVERAGE(CT15:CT16) -> 0.0075 | CU13: =AVERAGE(CU15:CU16) -> 0.0175 | CV13: =AVERAGE(CV15:CV16) -> 0.66 | CW13: =AVERAGE(CW15:CW16) -> 0.315 | FO13: 2G | FP13: 0 | FQ13: 0 | FR13: 0.5 | FS13: 0.5 | FT13: 0 | FU13: 0 | FV13: 0 | IM13: Last meeting suggestion
FH14: Nekane | FI14: 0.035 | FJ14: 0.085 | FK14: 0 | FL14: 0.048 | FO14: 3G | FP14: 0 | FQ14: 0 | FR14: 0.5 | FS14: 0 | FT14: 0.5 | FU14: 0 | FV14: 0 | IM14: Brzozek C, Zeleke BM, Abramson MJ, Benke KK, Benke G. Radiofrequency electromagnetic field exposure assessment: A pilot study on mobile phone signal strength and transmitted power levels. Journal of Exposure Science & Environmental Epidemiology. 2021 Jan;31(1):62-9. | IN14: 11% of activity with phone has been recorded for wifi. Not only call.
CS15: r | CT15: 0.01 | CU15: 0.03 | CV15: 0.88 | CW15: 0.08 | CX15: 0 | CY15: 0.03 | CZ15: 0.88 | DA15: 0.08 | FH15: Bram, | FI15: =AVERAGE(4.18,4.48,9.94,1.83)/100 -> 0.051075 | FJ15: =AVERAGE(1.93,2.99,4.47,1.1)/100 -> 0.026225 | FK15: 0 | FL15: =AVERAGE(1.62,0.61,7.18,12.51)/100 -> 0.0548 | FO15: 4G | FP15: 0.04 | FQ15: 0.19 | FR15: 0.21 | FS15: 0.28 | FT15: 0.19 | FU15: 0.09 | FV15: 0 | IM15: Ericsson Mobility Report, November 2025. Central and Eastern European Countries
CS16: d | CT16: 0.005 | CU16: 0.005 | CV16: 0.44 | CW16: 0.55 | CX16: 0 | CY16: 0.01 | CZ16: 0.44 | DA16: 0.55 | FH16: Application-dependent transmit power for auto-induced uplink exposure assessment from in-situ mobile phone usage in four European countries | FO16: 5G | FP16: 0 | FQ16: 0 | FR16: 0 | FS16: 0 | FT16: 0 | FU16: 0 | FV16: 1 | IM16: Ericsson Mobility Report, November 2025. west European countries
CT17: new number | CU17: new number | CV17: new number | CW17: new number | CX17: new number | CY17: new number | CZ17: new number | DA17: new number | IM17: IEM
IM18: IEM
AS19: note | CS19: sd | CT19: =STDEVA(CT15:CT16) -> 0.0035355339 | CU19: =STDEVA(CU15:CU16) -> 0.01767767 | CV19: =STDEVA(CV23:CV24) -> 0.021213203 | CW19: =STDEVA(CW15:CW16) -> 0.33234019 | CY19: =STDEVA(CY15:CY16) -> 0.014142136 | CZ19: =STDEVA(CZ15:CZ16) -> 0.31112698 | DA19: =CW19 -> 0.33234019 | DD19: =STDEVA(DD21,DD61) -> 262.85734 | DE19: =STDEVA(DE60,DE21) -> 48.830381 | DF19: =STDEVA(DF61,DF21) -> 702.13512 | DG19: =STDEVA(DG60,DG21) -> 130.43397 | DH19: =STDEVA(DH61,DH21) -> 575.25496 | DI19: =STDEVA(DI60,DI21) -> 106.86374 | DJ19: =DG19 -> 130.43397 | DK19: =STDEVA(DK20:DK62) -> 0.69248345 | DL19: =STDEVA(DL20,DL21,DL36,DL62) -> 0.18408485 | DM19: ? | DN19: =STDEVA(DN21,DN36) -> 0.32948095 | DO19: ? | DP19: ? | DQ19: =DN19 -> 0.32948095 | EG19: =STDEVA(EG20:EG31) -> 0.8131728 | FE19: =STDEVA(FE30:FE34) -> 0 | FF19: 0 | FG19: =STDEVA(FG30:FG33) -> 0.025057983 | FH19: =STDEVA(FH30:FH32) -> 0.14432326 | FI19: =STDEVA(FI14:FI15) -> 0.011366742 | FJ19: =STDEVA(FJ14:FJ15) -> 0.041560201 | FK19: =STDEVA(FK14:FK15) -> 0 | FL19: =STDEVA(FL14:FL15) -> 0.0048083261 | FM19: =STDEVA(FM43:FM50) -> 0.013709559 | FN19: =STDEVA(FN52:FN55) -> 0.0099853226 | IM19: Persson T, Törnevik C, Larsson LE, Lovén J. Output power distributions of terminals in a 3G mobile communication network. Bioelectromagnetics. 2012;33(4):320-5.
AS20: user is free to select all these three items or just one of them or maybe two of them. | DK20: 1.08 | DL20: =DK20*(10^(-3.7/10)) -> 0.46070588 | EG20: 1.18 | IM20: Paljanos A, Miclăuș S, Bechet P, Munteanu C. Assessment of mobile phone user exposure to UMTS and LTE signals: comparative near-field radiated power levels for various data and voice application services. Journal of Electromagnetic Waves and Applications. 2016;30(9):1101-15.
AS21: if user did not select any item, consider default values (0.333, 0.333, 0.333) | CT21: =SUM(CT13:CW13) -> 1 | DD21: 189 | DE21: =DD5*(10^(-4.3/10)) -> 139.27675 | DF21: 1778 | DG21: =DF5*(10^(-4.3/10)) -> 476.12815 | DH21: 1778 | DI21: =DH5*(10^(-4.3/10)) -> 509.46149 | DK21: 0.03 | DL21: =DK21*(10^(-3.7/10)) -> 0.012797386 | DM21: 2.03 | DN21: =DM21*(10^(-3.7/10)) -> 0.86595642 | DO21: 6.2 | DP21: =DO21*(10^(-3.7/10)) -> 2.644793 | IM21: Popović M, Koprivica M, Milinković J, Nešković A. Experimental analysis of individual EMF exposure for GSM/UMTS/WLAN user devices. Annals of Telecommunications. 2019 Feb 1;74:79-91. | IN21: skype voce call, mean value of three signal qualities good medium bad
DA22: sam as pure 5G | DG22: 4.3 dB factor indoor-outdoor | DI22: 4.3 dB factor indoor-outdoor | DL22: 3.7 dB factor indoor-outdoor | DN22: 3.7 dB factor indoor-outdoor | DP22: 3.7 dB factor indoor-outdoor | IM22: Bürgi A, Frei P, Theis G, Mohler E, Braun‐Fahrländer C, Fröhlich J, Neubauer G, Egger M, Röösli M. A model for radiofrequency electromagnetic field predictions at outdoor and indoor locations in the context of epidemiological research. Bioelectromagnetics: Journal of the Bioelectromagnetics Society, The Society for Physical Regulation in Biology and Medicine, The European Bioelectromagnetics Association. 2010 Apr;31(3):226-36.
AS23: if user select one items, it means 100% or 1 for that item and ziro value for the rest (1, 0, 0).considering this numbers atr important because they multipled in other boxes and have effect on other cells. If user select two, it means 50% (0.5) and 50% (0.5) for example for pocket and far | CV23: =SUM(CV15:CW15) -> 0.96 | IM23: Joshi P, Colombi D, Thors B, Larsson LE, Törnevik C. Output Power Levels of 4G User Equipment and Implications on Realistic RF EMF Exposure Assessments. IEEE Access. 2017;5:4545-50.
CV24: =SUM(CV16:CW16) -> 0.99 | IM24: Joshi P, Ghasemifard F, Colombi D, Törnevik C. Actual output power levels of user equipment in 5G commercial networks and implications on realistic RF EMF exposure assessment. IEEE Access. 2020;8:204068-75.
IM25: Joseph W, Pareit D, Vermeeren G, Naudts D, Verloock L, Martens L, et al. Determination of the duty cycle of WLAN for realistic radio frequency electromagnetic field exposure assessment. Prog Biophys Mol Biol. 2013;111(1):30-6.
IM26: van Wel L, Liorni I, Huss A, Thielens A, Wiart J, Joseph W, et al. Radio-frequency electromagnetic field exposure and contribution of sources in the general population: an organ-specific integrative exposure assessment. J Expo Sci Environ Epidemiol. 2021;31(6):999-1007.
IM27: Joseph W, Pareit D, Vermeeren G, Naudts D, Verloock L, Martens L, et al. Determination of the duty cycle of WLAN for realistic radio frequency electromagnetic field exposure assessment. Prog Biophys Mol Biol. 2013;111(1):30-6.
IN28: these data has been extracted from graph with estimaation of median value
IM29: Popović M, Koprivica M, Milinković J, Nešković A. Experimental analysis of individual EMF exposure for GSM/UMTS/WLAN user devices. Annals of Telecommunications. 2019 Feb 1;74:79-91.
EG30: 0.03 | EH30: =EG5*(10^(-3.7/10)) -> 0.25808061 | EI30: 2.04 | EJ30: =EI30*(10^(-3.7/10)) -> 0.87022222 | EK30: 6.28 | EL30: =EK30*(10^(-3.7/10)) -> 2.6789194 | FG30: 0.979 | FH30: 0.4592 | IM30: Popović M, Koprivica M, Milinković J, Nešković A. Experimental analysis of individual EMF exposure for GSM/UMTS/WLAN user devices. Annals of Telecommunications. 2019 Feb 1;74:79-91. | IN30: good UMTS 2100 connection
EH31: 3.7 dB damping factor indoor-outdoor | EJ31: 3.7 dB damping factor indoor-outdoor | EL31: 3.7 dB damping factor indoor-outdoor | EM31: same as outdoor | FG31: 0.9441 | FH31: 0.4633 | IM31: Popović M, Koprivica M, Milinković J, Nešković A. Experimental analysis of individual EMF exposure for GSM/UMTS/WLAN user devices. Annals of Telecommunications. 2019 Feb 1;74:79-91. | IN31: medium UMTS 2100 connection
DR32: Nekane data | DY32: Nekane data | FG32: 0.994 | FH32: 0.7112 | IM32: Popović M, Koprivica M, Milinković J, Nešković A. Experimental analysis of individual EMF exposure for GSM/UMTS/WLAN user devices. Annals of Telecommunications. 2019 Feb 1;74:79-91. | IN32: bad UMTS 2100 connection
Q33: SAR | FE33: 0.12 | FG33: 1 | IM33: Calderón C, Castano-Vinyals G, Maslanyj M, Wiart J, Lee AK, Taki M, Wake K, Abert A, Badia F, Hadjem A, Kromhout H. Estimation of RF and ELF dose by anatomical location in the brain from wireless phones in the MOBI-Kids study. Environment international. 2022 May 1;163:107189.
S34: Brain | Y34: WB | AE34: Brain | AF34: WB | DJ34: 61 | FE34: 0.12 | IM34: Vrijheid M, Mann S, Vecchia P, Wiart J, Taki M, Ardoino L, Armstrong BK, Auvinen A, Bédard D, Berg-Beckhoff G, Brown J. Determinants of mobile phone output power in a multinational study: implications for exposure assessment. Occupational and environmental medicine. 2009 Oct 1;66(10):664-71.
S35: Ear | T35: agregated_phone_position_(during headset use) | U35: front of face | V35: pocket | W35: Far | X35: speaker(front of mouth) | Y35: Ear | Z35: agregated_phone_position_(during headset use) | AA35: front of face | AB35: pocket | AC35: Far | AD35: speaker(front of mouth) | AE35: weighted_total | AF35: weighted_total | AJ35: 0.03907704 | AK35: 0.0068410157 | DJ35: 161
Q36: Call_SAR | R36: 2G (900, 1800) | S36: =SUMPRODUCT($FP$13:$FV$13,FW5:GC5) -> 0.080977377 | T36: =$AS$5*U36+$AT$5*V36+$AU$5*W36 -> 0.0013671032 | U36: =SUMPRODUCT($FP$13:$FV$13,GR5:GX5) -> 0.0041017675 | V36: =SUMPRODUCT($FP$13:$FV$13,GK5:GQ5) -> 3.6474719e-06 | W36: 0 | X36: =SUMPRODUCT($FP$13:$FV$13,GD5:GJ5) -> 0.0072587091 | Y36: =SUMPRODUCT($FP$13:$FV$13,GY5:HE5) -> 0.011696558 | Z36: =$AS$5*AA36+$AT$5*AB36+$AU$5*AC36 -> 0.0036476698 | AA36: =SUMPRODUCT($FP$13:$FV$13,HT5:HZ5) -> 0.0010726152 | AB36: =SUMPRODUCT($FP$13:$FV$13,HM5:HS5) -> 0.0098813483 | AC36: 0 | AD36: =SUMPRODUCT($FP$13:$FV$13,HF5:HL5) -> 0.0023081272 | AE36: =$AQ$5*S36+$AR$5*T36+$AV$5*X36 -> 0.038915611 | AF36: =$AQ$5*Y36+$AR$5*Z36+$AV$5*AD36 -> 0.0068193806 | AJ36: 0.036748705 | AK36: 0.0066566705 | DK36: 1.7 | DL36: 0.2 | DN36: 0.4 | DQ36: 0.15 | IM36: Gati A, Hadjem A, Wong MF, Wiart J. Exposure induced by WCDMA mobiles phones in operating networks. IEEE Transactions on wireless communications. 2009 Dec 11;8(12):5723-7.
R37: 3G (900, 2100) | S37: =SUMPRODUCT($FP$14:$FV$14,FW5:GC5) -> 0.076177772 | T37: =$AS$5*U37+$AT$5*V37+$AU$5*W37 -> 0.0012757832 | U37: =SUMPRODUCT($FP$14:$FV$14,GR5:GX5) -> 0.0038276323 | V37: =SUMPRODUCT($FP$14:$FV$14,GK5:GQ5) -> 3.5484087e-06 | W37: 0 | X37: =SUMPRODUCT($FP$14:$FV$14,GD5:GJ5) -> 0.0067977406 | Y37: =SUMPRODUCT($FP$14:$FV$14,GY5:HE5) -> 0.011423966 | Z37: =$AS$5*AA37+$AT$5*AB37+$AU$5*AC37 -> 0.0034955572 | AA37: =SUMPRODUCT($FP$14:$FV$14,HT5:HZ5) -> 0.0010617191 | AB37: =SUMPRODUCT($FP$14:$FV$14,HM5:HS5) -> 0.0094354496 | AC37: 0 | AD37: =SUMPRODUCT($FP$14:$FV$14,HF5:HL5) -> 0.0022247114 | AE37: =$AQ$5*S37+$AR$5*T37+$AV$5*X37 -> 0.036596764 | AF37: =$AQ$5*Y37+$AR$5*Z37+$AV$5*AD37 -> 0.0066354928 | AJ37: 0.036128107 | AK37: 0.0066503266 | DJ37: 40.7 | DQ37: 1.72 | IM37: Kelsh MA, Shum M, Sheppard AR, Mcneely M, Kuster N, Lau E, Weidling R, Fordyce T, Kühn S, Sulser C. Measured radiofrequency exposure during various mobile-phone use scenarios. Journal of Exposure Science & Environmental Epidemiology. 2011 Jul;21(4):343-54.
R38: 4G ( 700 to 2600) | S38: =SUMPRODUCT($FP$15:$FV$15,FW5:GC5) -> 0.075016093 | T38: =$AS$5*U38+$AT$5*V38+$AU$5*W38 -> 0.001200065 | U38: =SUMPRODUCT($FP$15:$FV$15,GR5:GX5) -> 0.0035994191 | V38: =SUMPRODUCT($FP$15:$FV$15,GK5:GQ5) -> 4.3796059e-06 | W38: 0 | X38: =SUMPRODUCT($FP$15:$FV$15,GD5:GJ5) -> 0.0065464082 | Y38: =SUMPRODUCT($FP$15:$FV$15,GY5:HE5) -> 0.011416455 | Z38: =$AS$5*AA38+$AT$5*AB38+$AU$5*AC38 -> 0.0034733674 | AA38: =SUMPRODUCT($FP$15:$FV$15,HT5:HZ5) -> 0.0010361509 | AB38: =SUMPRODUCT($FP$15:$FV$15,HM5:HS5) -> 0.009394382 | AC38: 0 | AD38: =SUMPRODUCT($FP$15:$FV$15,HF5:HL5) -> 0.0022313982 | AE38: =$AQ$5*S38+$AR$5*T38+$AV$5*X38 -> 0.035978107 | AF38: =$AQ$5*Y38+$AR$5*Z38+$AV$5*AD38 -> 0.0066291954 | AJ38: 0.0028501102 | AK38: 0.0058640449 | DJ38: 34.35 | IM38: Kelsh MA, Shum M, Sheppard AR, Mcneely M, Kuster N, Lau E, Weidling R, Fordyce T, Kühn S, Sulser C. Measured radiofrequency exposure during various mobile-phone use scenarios. Journal of Exposure Science & Environmental Epidemiology. 2011 Jul;21(4):343-54.
R39: 5G (3500) | S39: =GC5 -> 0.0055389929 | T39: =$AS$5*U39+$AT$5*V39+$AU$5*W39 -> 0.00022368506 | U39: =GX5 -> 0.00067149569 | V39: =GQ5 -> 2.3122642e-07 | W39: 0 | X39: =GJ5 -> 0.00095661199 | Y39: =HE5 -> 0.0093079113 | Z39: =$AS$5*AA39+$AT$5*AB39+$AU$5*AC39 -> 0.0016019779 | AA39: =HZ5 -> 0.0007262761 | AB39: =HS5 -> 0.0040844685 | AC39: 0 | AD39: =HS5 -> 0.0040844685 | AE39: =$AQ$5*S39+$AR$5*T39+$AV$5*X39 -> 0.0028402645 | AF39: =$AQ$5*Y39+$AR$5*Z39+$AV$5*AD39 -> 0.00585367 | AJ39: 0.012611403 | AK39: 0.0056211952
R40: WiFi 2.4 GHz | AE40: =$AQ$5*BI5+$AR$5*BJ5+$AV$5*BN5 -> 0.012555857 | AF40: =$AQ$5*BO5+$AR$5*BP5+$AV$5*BT5 -> 0.0056024498 | AJ40: 0.00059909692 | AK40: 0.003581048
...

Sheet MobileData
B1: Total_dose_mobile_data | D1: Duration_total | E1: connection mode_transmitter_weighted_m_SAR | G1: transmitter_weighted_m_SAR | U1: transmitter_position_weighted_SAR | AF1: SAR_wifi | AJ1: Connectivity_mode | AL1: technology_contribution | AO1: technology_power | AR1: Wifi_contribution | AT1: Wifi_power | AV1: duration_data_transfer | AZ1: online activity contribution | BD1: 3G_duty_cycle | BH1: 4G_duty_cycle | BL1: 5G_duty_cycle | BP1: wifi2_duty_cycle | BT1: wifi5_duty_cycle | BX1: high_data_outputpower__mW | CU1: nSAR_belly
B2: mJ/kg/day | D2: second | G2: mobile_data | P2: WiFi | U2: mobile_data | AA2: WiFi | AE2: front_of_face | AF2: W/kg/W | AJ2: proportion | AL2: proportion | AO2: mW | AR2: proportion | AT2: mW | AV2: second | BX2: 3G | CE2: 4G | CL2: 5G | CS2: wifi
E3: brain | F3: wb | G3: brain | K3: WB | O3: brain | R3: WB | U3: brain | X3: WB | AA3: brain | AC3: WB | AF3: brain | AH3: WB | AJ3: data | AK3: wifi | AL3: 3G | AM3: 4G | AN3: 5G | AO3: 3G | AP3: 4G | AQ3: 5G | AR3: wifi2 | AS3: wifi5 | AT3: wifi2 | AU3: wifi5 | BX3: urban | BZ3: suburban | CB3: rural | CD3: traveling | CE3: urban | CG3: suburban | CI3: rural | CK3: traveling | CL3: urban | CN3: suburban | CP3: rural | CR3: traveling | CS3: wifi2 | CT3: wifi5 | CU3: brain | DD3: WB | DM3: Reference | DN3: Remarks
A4: variable | B4: brain | C4: WB | G4: total | H4: 3G | I4: 4G | J4: 5G | K4: total | L4: 3G | M4: 4G | N4: 5G | O4: total | P4: wifi2 | Q4: wifi5 | R4: total | S4: wifi2 | T4: wifi5 | U4: 3G | V4: 4G | W4: 5G | X4: 3G | Y4: 4G | Z4: 5G | AA4: wifi2 | AB4: wifi5 | AC4: wifi2 | AD4: wifi5 | AF4: wifi2 | AG4: wifi5 | AH4: wifi2 | AI4: wifi5 | AV4: browsing | AW4: audio | AX4: video | AY4: upload | AZ4: brwosing | BA4: voice | BB4: video | BC4: upload | BD4: brwosing | BE4: voice | BF4: video | BG4: upload | BH4: brwosing | BI4: voice | BJ4: video | BK4: upload | BL4: brwosing | BM4: voice | BN4: video | BO4: upload | BP4: brwosing | BQ4: voice | BR4: video | BS4: upload | BT4: brwosing | BU4: voice | BV4: video | BW4: upload | BX4: indoor | BY4: outdoor | BZ4: indoor | CA4: outdoor | CB4: indoor | CC4: outdoor | CE4: indoor | CF4: outdoor | CG4: indoor | CH4: outdoor | CI4: indoor | CJ4: outdoor | CL4: indoor | CM4: outdoor | CN4: indoor | CO4: outdoor | CP4: indoor | CQ4: outdoor | CU4: 700 | CV4: 800 | CW4: 900 | CX4: 1800 | CY4: 2100 | CZ4: 2400 | DA4: 2600 | DB4: 3500 | DC4: 5000 | DD4: 700 | DE4: 800 | DF4: 900 | DG4: 1800 | DH4: 2100 | DI4: 2400 | DJ4: 2600 | DK4: 3500 | DL4: 5000
A5: Summary | B5: =D5*E5 -> 146.94671 | C5: =D5*F5 -> 78.687031 | D5: =SUM(AV5:AY5) -> 14557.005 | E5: =G5*AJ5+O5*AK5 -> 0.01009457 | F5: =K5*AJ5+R5*AK5 -> 0.0054054411 | G5: =H5*AL5+I5*AM5+J5*AN5 -> 0.017927726 | H5: =U5*AO5 -> 0.20552639 | I5: =V5*AP5 -> 0.020097394 | J5: =W5*AQ5 -> 0.0033077029 | K5: =L5*AL5+M5*AM5+N5*AN5 -> 0.0059697609 | L5: =X5*AO5 -> 0.057009472 | M5: =Y5*AP5 -> 0.0057853593 | N5: =Z5*AQ5 -> 0.0035775443 | O5: =AR5*P5+AS5*Q5 -> 0.0051982319 | P5: =AT5*AA5 -> 0.0070834841 | Q5: =AU5*AB5 -> 0.0025947884 | R5: =AR5*S5+AS5*T5 -> 0.0050526968 | S5: =AC5*AT5 -> 0.0054614369 | T5: =AU5*AD5 -> 0.0044882463 | U5: =P77*AE5 -> 0.0038276323 | V5: =P78*AE5 -> 0.0035994191 | W5: =P79*AE5 -> 0.00067149569 | X5: =S77*AE5 -> 0.0010617191 | Y5: =S78*AE5 -> 0.0010361509 | Z5: =S79*AE5 -> 0.0007262761 | AA5: =P80*AE5 -> 0.0011194632 | AB5: =P81*AE5 -> 0.00032007162 | AC5: =S80*AE5 -> 0.00086311725 | AD5: =S81*AE5 -> 0.00055363292 | AE5: 1 | AF5: =MobileCall!BK5 -> 0.0011194632 | AG5: =MobileCall!BW5 -> 0.00032007162 | AH5: =MobileCall!BQ5 -> 0.00086311725 | AI5: =MobileCall!CC5 -> 0.00055363292 | AJ5: =MobileCall!IC5 -> 0.38464516 | AK5: =MobileCall!ID5 -> 0.61535484 | AL5: =MobileCall!CY5 -> 0.0175 | AM5: =MobileCall!CZ5 -> 0.66 | AN5: =MobileCall!DA5 -> 0.3225 | AO5: =((Farfield!N5+Farfield!P5)*( AZ5*BD5*BZ5+BA5*BE5*BZ5+BB5*BF5*BZ5+BC5*BG5*BZ5))+ (Farfield!O5* (AZ5*BD5*CA5+BA5*BE5*CA5+BB5*BF5*CA5+BC5*BG5*CA5))+ (Farfield!Q5*(AZ5*BD5*CD5+BA5*BE5*CD5+BB5*BF5*CD5+BC5*BG5*CD5)) -> 53.695438 | AP5: =((Farfield!N5+Farfield!P5)*( AZ5*BH5*CG5+BA5*BI5*CG5+BB5*BJ5*CG5+BC5*BK5*CG5))+ (Farfield!O5* (AZ5*BH5*CH5+BA5*BI5*CH5+BB5*BJ5*CH5+BC5*BK5*CH5))+ (Farfield!Q5*(AZ5*BH5*CK5+BA5*BI5*CK5+BB5*BJ5*CK5+BC5*BK5*CK5)) -> 5.5835105 | AQ5: =((Farfield!N5+Farfield!P5)*( AZ5*BL5*CN5+BA5*BM5*CN5+BB5*BN5*CN5+BC5*BO5*CN5))+ (Farfield!O5* ( AZ5*BL5*CO5+BA5*BM5*CO5+BB5*BN5*CO5+BC5*BO5*CO5))+ (Farfield!Q5*(AZ5*BL5*CR5+BA5*BM5*CR5+BB5*BN5*CR5+BC5*BO5*CR5)) -> 4.9258736 | AR5: =MobileCall!DB5 -> 0.58 | AS5: =MobileCall!DC5 -> 0.42 | AT5: =(AZ5*BP5*CS5+BA5*BQ5*CS5+BB5*BR5*CS5+BC5*BS5*CS5) -> 6.3275724 | AU5: =(AZ5*BT5*CT5+BA5*BU5*CT5+BB5*BV5*CT5+BC5*BW5*CT5) -> 8.1068992 | AV5: =[1]Sheet1!$B$13 -> 3989.3181 | AW5: =[1]Sheet1!$B$14 -> 4916.9717 | AX5: =[1]Sheet1!$B$15 -> 5650.7148 | AY5: 0 | AZ5: =AV5/D5 -> 0.27404801 | BA5: =AW5/D5 -> 0.33777359 | BB5: =AX5/D5 -> 0.3881784 | BC5: =AY5/D5 -> 0 | BD5: 0.438 | BE5: 0.505 | BF5: 0.542 | BG5: 0.783 | BH5: =BI5/10 -> 0.00556125 | BI5: =AVERAGE(BI18,BI23) -> 0.0556125 | BJ5: =AVERAGE(BJ18,BJ23) -> 0.1344125 | BK5: 1 | BL5: =BM5/10 -> 0.00514 | BM5: =AVERAGE(BM18,BM23) -> 0.0514 | BN5: =AVERAGE(BN18,BN23) -> 0.2160375 | BO5: 1 | BP5: =AVERAGE(BP27:BP31) -> 0.0086 | BQ5: =AVERAGE(BQ20:BQ30) -> 0.02201 | BR5: =BR58 -> 0.13778333 | BS5: =AVERAGE(BS26:BS31) -> 0.67064 | BT5: =AVERAGE(BT34:BT37) -> 0.024275 | BU5: =AVERAGE(BU34:BU45) -> 0.038625 | BV5: =AVERAGE(BV34:BV49) -> 0.053675 | BW5: =AVERAGE(BW34:BW37) -> 0.494775 | BX5: =10^(2.64/10) -> 1.8365383 | BY5: =BX5*(10^(-3.7/10)) -> 0.78342964 | BZ5: =10^(20.57/10) -> 114.02498 | CA5: =BZ5*(10^(-3.7/10)) -> 48.640721 | CB5: =10^(CB30/10) -> 167.10906 | CC5: =CB5*(10^(-3.7/10)) -> 71.285303 | CD5: 48.64 | CE5: =MobileCall!EN5 -> 64.105638 | CF5: =MobileCall!EO5 -> 54.479069 | CG5: =MobileCall!EP5 -> 77.898518 | CH5: =MobileCall!EQ5 -> 68.405662 | CI5: =MobileCall!ER5 -> 91.691398 | CJ5: =MobileCall!ES5 -> 82.332255 | CK5: =MobileCall!ET5 -> 74.3 | CL5: =MobileCall!EU5 -> 46.35 | ... CT5: =MobileCall!FC5 -> 200 | CU5: 3.3334105e-05 | CV5: 2.4300659e-05 | CW5: 1.6262291e-05 | CX5: 1.9669471e-06 | CY5: 1.3806738e-06 | CZ5: 4.7510979e-07 | DA5: 4.1307496e-07 | DB5: 1.6677806e-07 | DC5: 2.1402708e-08 | DD5: 0.01265673 | DE5: 0.012442919 | DF5: 0.012197826 | DG5: 0.012356118 | DH5: 0.0093095822 | DI5: 0.010153247 | DJ5: 0.0071090368 | DK5: 0.0047746416 | DL5: 0.0026463741
A6: user_inputs
A7: single data | D7: 47 | DM7: Young people spend a lot of time on their smartphones every day
D8: 59.6 | AV8: I considered 50-50 for data activities with high and low data transfer. If the user changes this, | DM8: Smartphone Usage Statistics for 2025 (Surprising)
D9: 146 | AF9: cell addressed to a another cell | AG9: cell addressed to a another cell | AH9: cell addressed to a another cell | AI9: cell addressed to a another cell | DM9: Statista. DIGITAL & TRENDS: Mobile internet usage in Europe. 2022.
D10: 56 | AV10: important point | CD10: I USED SUBURBAN OUTDOOR HERE BECAUSE I DID NOT FIND VALUE FOR THIS SCENARIO | DM10: Aktuelle Aspekte der Internetnutzung in Deutschland ARD/ZDF-Onlinestudie: Weitergehende Normalisierung der Internetnutzung nach Wegfall aller Corona-Schutzmaßnahmen Von Natalie Beisch* und Wolfgang Koch*
AV11: if user changes the time durations for low or high, the total duration (D5) will be sum up of these two low and high durations | BH11: new number | BI11: new number | BJ11: new number | BK11: new number | BL11: new number | BM11: new number | BN11: new number | BO11: new number | DM11: Basic Data Children and Media 2024 Current surveys and research on media use among children in Germany Compiled by
DM12: Basic Data Adolescents and Media 2024 Current surveys and research on media use among Adolescents in Germany Compiled by Heike vom Orde (IZI) and Dr. Alexandra Durner
AP13: WHY THI IS HIGH? BECAUSE WE SPENT MORE TIME INDOOR
DM14: while there is no data call/activity on 2G, 4% and 2% network removed and added to other technologies
B15: D5*E5*G5 | C15: D5*G5*F5 | DM15: while there is no data call/activity on 2G, 4% and 2% network removed and added to other technologies
BR16: 0.019 | DM16: Paljanos A, Miclăuș S, Bechet P, Munteanu C. Assessment of mobile phone user exposure to UMTS and LTE signals: comparative near-field radiated power levels for various data and voice application services. Journal of Electromagnetic Waves and Applications. 2016;30(9):1101-15.
D17: for default value, D5 is an average of internet activies. Addtionally we assumed that this activity is 50-50 low and high data transfer | BH17: 1/10 of voice | BI17: Nekane data | BJ17: Nekane data | BK17: average of Nekane and Bram data | BL17: 1/10 of voice | BM17: Nekane data | BN17: Nekane data | BO17: average of Nekane and Bram data | BR17: 0.0196
D18: The default value is 4629. but if the user change the sliders, please sum up the slider values and consider it as Duration (D5 cell) | BI18: 0.085 | BJ18: 0.208 | BK18: a | BM18: 0.048 | BN18: 0.347 | BR18: 0.0351
BJ19: Nekane data | BK19: 0.767 | BO19: 0.397939 | BR19: 0.0877 | BT19: NEW NUMBERS | BU19: NEW NUMBERS | BV19: NEW NUMBERS | BW19: NEW NUMBERS | DM19: Persson T, Törnevik C, Larsson LE, Lovén J. Output power distributions of terminals in a 3G mobile communication network. Bioelectromagnetics. 2012;33(4):320-5.
BJ20: Bram | BK20: 0.722 | BO20: 0.404 | BQ20: 0.0013 | BR20: 0.1341
BD21: =AVERAGE(BD22:BD24) -> 43.8 | BQ21: 0.067 | BR21: 0.2032
BD22: 49.17 | BJ22: average | BK22: =AVERAGE(BK19:BK20) -> 0.7445 | BO22: =AVERAGE(BO19:BO20) -> 0.4009695 | BQ22: 0.008
BD23: 50.74 | BH23: bram | BI23: =MobileCall!FJ15 -> 0.026225 | BJ23: =AVERAGE(5.22,4.06,14.19,0.86)/100 -> 0.060825 | BM23: =MobileCall!FL15 -> 0.0548 | BN23: =AVERAGE(4.64,2.2,10.7,16.49)/100 -> 0.085075 | BQ23: 0.031 | DM23: Joseph W, Pareit D, Vermeeren G, Naudts D, Verloock L, Martens L, et al. Determination of the duty cycle of WLAN for realistic radio frequency electromagnetic field exposure assessment. Prog Biophys Mol Biol. 2013;111(1):30-6.
BD24: 31.49 | BR24: 0.0108 | DM24: Joseph W, Pareit D, Vermeeren G, Naudts D, Verloock L, Martens L, et al. Determination of the duty cycle of WLAN for realistic radio frequency electromagnetic field exposure assessment. Prog Biophys Mol Biol. 2013;111(1):30-6.
BQ25: 0.0222 | BR25: 0.0235 | DM25: Joseph W, Pareit D, Vermeeren G, Naudts D, Verloock L, Martens L, et al. Determination of the duty cycle of WLAN for realistic radio frequency electromagnetic field exposure assessment. Prog Biophys Mol Biol. 2013;111(1):30-6.
BQ26: 0.0302 | BR26: 0.1069 | BS26: 0.4618 | DM26: Joseph W, Pareit D, Vermeeren G, Naudts D, Verloock L, Martens L, et al. Determination of the duty cycle of WLAN for realistic radio frequency electromagnetic field exposure assessment. Prog Biophys Mol Biol. 2013;111(1):30-6.
BP27: 0.0025 | BQ27: 0.0455 | BR27: 0.0542 | BS27: 0.8741 | DM27: Joseph W, Pareit D, Vermeeren G, Naudts D, Verloock L, Martens L, et al. Determination of the duty cycle of WLAN for realistic radio frequency electromagnetic field exposure assessment. Prog Biophys Mol Biol. 2013;111(1):30-6.
BE28: 0.15 | BP28: 0.0157 | BQ28: 0.004 | BR28: 0.1454 | DM28: Popović M, Koprivica M, Milinković J, Nešković A. Experimental analysis of individual EMF exposure for GSM/UMTS/WLAN user devices. Annals of Telecommunications. 2019 Feb 1;74:79-91.
BE29: 10 | BP29: 0.0089 | BQ29: 0.0053 | BR29: 0.8139 | BS29: 0.5681 | CF29: numbers rplaced here | DM29: Popović M, Koprivica M, Milinković J, Nešković A. Experimental analysis of individual EMF exposure for GSM/UMTS/WLAN user devices. Annals of Telecommunications. 2019 Feb 1;74:79-91.
BP30: 0.0068 | BQ30: 0.0056 | BS30: 0.7126 | BX30: 2.64 | BY30: damping factor of 3.7 dB | BZ30: 20.57 | CA30: damping factor of 3.7 dB | CB30: 22.23 | CC30: damping factor of 3.7 dB | DM30: Popović M, Koprivica M, Milinković J, Nešković A. Experimental analysis of individual EMF exposure for GSM/UMTS/WLAN user devices. Annals of Telecommunications. 2019 Feb 1;74:79-91.
BP31: 0.0091 | BS31: 0.7366 | DM31: Popović M, Koprivica M, Milinković J, Nešković A. Experimental analysis of individual EMF exposure for GSM/UMTS/WLAN user devices. Annals of Telecommunications. 2019 Feb 1;74:79-91.
DM32: Popović M, Koprivica M, Milinković J, Nešković A. Experimental analysis of individual EMF exposure for GSM/UMTS/WLAN user devices. Annals of Telecommunications. 2019 Feb 1;74:79-91.
BI33: =STDEVA(BI18,BI23) -> 0.041560201 | BJ33: =STDEVA(BJ18,BJ23) -> 0.10406844 | BK33: =STDEVA(BK18,BK23) -> #DIV/0! | BL33: =STDEVA(BL18,BL23) -> #DIV/0! | BM33: =STDEVA(BM18,BM23) -> 0.0048083261 | BN33: =STDEVA(BN18,BN23) -> 0.18520894 | BO33: =STDEVA(BO18,BO23) -> #DIV/0! | BP33: =STDEV(BP27:BP31) -> 0.0047749346 | BQ33: =STDEV(BQ20:BQ34) -> 0.010767451 | BR33: =STDEV(BR16:BR29) -> 0.22151114 | BS33: =STDEVA(BS26:BS31) -> 0.15940195 | BT33: =STDEVA(BT34:BT37) -> 0.017089446 | BU33: =STDEVA(BU34:BU45) -> 0.030956571 | BV33: =STDEVA(BV34:BV49) -> 0.04278929 | BW33: =STDEVA(BW34:BW37) -> 0.41422092
BT34: 0.02 | BU34: 0.0523 | BV34: 0.0525 | BW34: 0.9429 | DM34: Yang, Y., Vermeeren, G., Verloock, L., Guxens, M., & Joseph, W. (2025). A Survey of IEEE 802.11ax WLAN Temporal Duty Cycle for the Assessment of RF Electromagnetic Exposure. Applied Sciences, 15(5), 2858. https://doi.org/10.3390/app15052858
BT35: 0.016 | BU35: 0.0613 | BV35: 0.0432 | BW35: 0.744 | DM35: Yang, Y., Vermeeren, G., Verloock, L., Guxens, M., & Joseph, W. (2025). A Survey of IEEE 802.11ax WLAN Temporal Duty Cycle for the Assessment of RF Electromagnetic Exposure. Applied Sciences, 15(5), 2858. https://doi.org/10.3390/app15052859
BT36: 0.0494 | BU36: 0.0459 | BV36: 0.1899 | BW36: 0.0803 | DM36: Yang, Y., Vermeeren, G., Verloock, L., Guxens, M., & Joseph, W. (2025). A Survey of IEEE 802.11ax WLAN Temporal Duty Cycle for the Assessment of RF Electromagnetic Exposure. Applied Sciences, 15(5), 2858. https://doi.org/10.3390/app15052860
BT37: 0.0117 | BU37: 0.0377 | BV37: 0.031 | BW37: 0.2119 | DM37: Yang, Y., Vermeeren, G., Verloock, L., Guxens, M., & Joseph, W. (2025). A Survey of IEEE 802.11ax WLAN Temporal Duty Cycle for the Assessment of RF Electromagnetic Exposure. Applied Sciences, 15(5), 2858. https://doi.org/10.3390/app15052861
BU38: 0.0073 | BV38: 0.0118 | DM38: Yang, Y., Vermeeren, G., Verloock, L., Guxens, M., & Joseph, W. (2025). A Survey of IEEE 802.11ax WLAN Temporal Duty Cycle for the Assessment of RF Electromagnetic Exposure. Applied Sciences, 15(5), 2858. https://doi.org/10.3390/app15052862
BU39: 0.0081 | BV39: 0.0127 | DM39: Yang, Y., Vermeeren, G., Verloock, L., Guxens, M., & Joseph, W. (2025). A Survey of IEEE 802.11ax WLAN Temporal Duty Cycle for the Assessment of RF Electromagnetic Exposure. Applied Sciences, 15(5), 2858. https://doi.org/10.3390/app15052863
BU40: 0.1147 | BV40: 0.0388
...

Sheet Cordless
B1: Total_dose_cordless | D1: Duration | E1: Agregated_mSAR | G1: postion_aggregated_nSAR | I1: Agregated_power | J1: Positions | L1: SAR | P1: power | Q1: duty_cycle
B2: mJ/kg/day | C2: mJ/kg/day | D2: second | E2: W/kg/W | G2: W/kg/W | I2: mW | J2: proportion | L2: W/kg/W | P2: mW | Q2: proportion
A3: source | B3: brain | C3: WB | E3: brain | F3: WB | G3: brain | H3: WB | J3: ear | K3: speaker | L3: brain | N3: WB | R3: Reference | S3: Remarks
A4: variable | L4: ear | M4: speaker | N4: ear | O4: speaker
A5: Summary | B5: =D5*E5 -> 12.484726 | C5: =D5*F5 -> 3.5809795 | D5: =[1]Sheet1!$B$7 -> 68.825784 | E5: =G5*I5 -> 0.18139607 | F5: =H5*I5 -> 0.052029622 | G5: =(L5*J5)+(M5*K5) -> 0.018139607 | H5: =(N5*J5)+(O5*K5) -> 0.0052029622 | I5: =P5*Q5 -> 10 | J5: =[1]Sheet1!$B$8 -> 0.34601031 | K5: =1-J5 -> 0.65398969 | L5: =MobileCall!FZ5 -> 0.046356407 | M5: =MobileCall!GG5 -> 0.0032107719 | N5: =MobileCall!HB5 -> 0.011088893 | O5: =MobileCall!HI5 -> 0.0020888569 | P5: 250 | Q5: =AVERAGE(Q12:Q13) -> 0.04
A6: user_inputs
D7: 6.4 | R7: van Wel L, Liorni I, Huss A, Thielens A, Wiart J, Joseph W, et al. Radio-frequency electromagnetic field exposure and contribution of sources in the general population: an organ-specific integrative exposure assessment. J Expo Sci Environ Epidemiol. 2021;31(6):999-1007.
D8: 0.4 | R8: Birks LE, van Wel L, Liorni I, Pierotti L, Guxens M, Huss A, et al. Radiofrequency electromagnetic fields from mobile communication: Description of modeled dose in brain regions and the body in European children and adolescents. Environmental research. 2021;193:110505
J9: 0.9 | K9: 0.1 | L9: cell addressed to another | M9: cell addressed to another | N9: cell addressed to another | O9: cell addressed to another | P9: max power over network | R9: expert opinion
R10: IEM
R11: Swerdlow AJ. Health Effects from Radiofrequency Electromagnetic Fields: . UK: Health Protection Agency; 2012.
Q12: 0.04 | R12: Calderón C, Castano-Vinyals G, Maslanyj M, Wiart J, Lee AK, Taki M, Wake K, Abert A, Badia F, Hadjem A, Kromhout H. Estimation of RF and ELF dose by anatomical location in the brain from wireless phones in the MOBI-Kids study. Environment international. 2022 May 1;163:107189.
Q13: 0.04 | R13: Health effects of RF-EMF Report of the independent Advisory Group on Non-ionising Radiation ... independent research groups have found no such effect on this; uk health protection agancy
L69: e during browsing or other very low data transfer activities (such as texting, emailing, etc.) over a wifi 2.4 GHz

Sheet Laptop
B1: Total_dose_laptop | D1: Duration | E1: transmitter_weighted_m_SAR | K1: transmitter_position_weighted_SAR | O1: Positions | Q1: SAR_wifi2 | U1: SAR_wifi5 | Y1: Connectivity_mode | Z1: wifi_technology | AB1: power | AD1: duration_data_transfer | AH1: online activity contribution | AL1: reference | AM1: remark
B2: mJ/kg/day | C2: mJ/kg/day | D2: second | F2: WiFi | O2: proportion | Q2: W/kg/W | U2: W/kg/W | Y2: proportion | Z2: proportion | AB2: mW | AD2: second | AE2: second | AF2: second | AG2: second
A3: source | B3: brain | C3: WB | E3: brain | H3: WB | K3: brain | M3: WB | Q3: brain | S3: WB | U3: brain | W3: WB | Y3: wifi | Z3: wifi2 | AA3: wifi5 | AB3: wifi2 | AC3: wifi5
A4: variable | E4: total | F4: wifi2 | G4: wifi5 | H4: total | I4: wifi2 | J4: wifi5 | K4: wifi2 | L4: wifi5 | M4: wifi2 | N4: wifi5 | O4: lap | P4: table | Q4: lap | R4: table | S4: lap | T4: table | U4: lap | V4: table | W4: lap | X4: table | AD4: browsing | AE4: audio | AF4: video | AG4: upload | AH4: brwosing | AI4: voice | AJ4: video | AK4: upload
A5: Summary | B5: =D5*E5 -> 0.70773816 | C5: =D5*H5 -> 101.3788 | D5: =SUM(AD5:AG5) -> 3952.3925 | E5: =Z5*F5+AA5*G5 -> 0.00017906576 | F5: =K5*AB5 -> 0.00026200716 | G5: =L5*AC5 -> 6.4527631e-05 | H5: =Z5*I5+AA5*J5 -> 0.025649982 | I5: =M5*AB5 -> 0.027236005 | J5: =N5*AC5 -> 0.02345976 | K5: =O5*Q5+P5*R5 -> 3.8175614e-05 | L5: =O5*U5+P5*V5 -> 7.8166024e-06 | M5: =O5*S5+P5*T5 -> 0.0039684076 | N5: =O5*W5+P5*X5 -> 0.0028418154 | O5: 0.2 | P5: 0.8 | Q5: =[4]Sheet1!$I$47 -> 3.4320344e-05 | R5: =[4]Sheet1!$I$57 -> 3.9139431e-05 | S5: =[5]Sheet1!$H$47 -> 0.0071055683 | T5: =[5]Sheet1!$H$57 -> 0.0031841174 | U5: =[4]Sheet1!$I$50 -> 2.2386717e-06 | V5: =[4]Sheet1!$I$60 -> 9.211085e-06 | W5: =[5]Sheet1!$H$50 -> 0.0054622742 | X5: =[5]Sheet1!$H$60 -> 0.0021867007 | Y5: 1 | Z5: =MobileCall!DB5 -> 0.58 | AA5: =MobileCall!DC5 -> 0.42 | AB5: =(AH5*MobileData!BP5*MobileCall!FB5+AI5*MobileData!BQ5*MobileCall!FB5+AJ5*MobileData!BR5*MobileCall!FB5+AK5*MobileData!BS5*MobileCall!FB5) -> 6.8632076 | AC5: =(AH5*MobileData!BT5*MobileCall!FC5+AI5*MobileData!BU5*MobileCall!FC5+AJ5*MobileData!BV5*MobileCall!FC5+AK5*MobileData!BW5*MobileCall!FC5) -> 8.2552019 | AD5: =[1]Sheet1!$B$17 -> 1068.9706 | AE5: =[1]Sheet1!$B$18 -> 1167.9695 | AF5: =[1]Sheet1!$B$19 -> 1715.4524 | AG5: 0 | AH5: =AD5/D5 -> 0.27046166 | AI5: =AE5/D5 -> 0.29550949 | AJ5: =AF5/D5 -> 0.43402885 | AK5: =AG5/D5 -> 0
A6: user_inputs
A7: single dat | D7: 126.6 | AL7: van Wel L, Liorni I, Huss A, Thielens A, Wiart J, Joseph W, et al. Radio-frequency electromagnetic field exposure and contribution of sources in the general population: an organ-specific integrative exposure assessment. J Expo Sci Environ Epidemiol. 2021;31(6):999-1007.
D8: 19.1 | Z8: I considered 50-50 for data activities with high and low data transfer. | AL8: Birks LE, van Wel L, Liorni I, Pierotti L, Guxens M, Huss A, et al. Radiofrequency electromagnetic fields from mobile communication: Description of modeled dose in brain regions and the body in European children and adolescents. Environmental research. 2021;193:110505
J9: 0.2 | K9: 0.8 | AL9: expert opinion
S10: 1 | Z10: important point | AL10: expert opinion
Z11: if user changes the time durations for low or high, the total duration (D5) will be sum up of these two low and high durations, otherwise we keep the defulat value
V13: calculation based on the laptop inputs (durations proportion) | W13: calculation based on the laptop inputs (durations proportion) | Z13: =D5/2 -> 1976.1963 | AA13: =D5/2 -> 1976.1963

Sheet Tablet
B1: Total_dose_tablet | D1: Duration | E1: connection mode_transmitter_weighted_m_SAR | G1: transmitter_weighted_m_SAR | M1: transmitter_position_weighted_SAR | R1: SAR_wifi2 | T1: SAR_wifi5 | V1: Connectivity_mode | W1: wifi_technology | Y1: power | AA1: duration_data_transfer | AE1: online activity contribution
B2: mJ/kg/day | C2: mJ/kg/day | D2: second | H2: WiFi | M2: WiFi | Q2: proportion | R2: W/kg/W | T2: W/kg/W | V2: proportion | W2: proportion | Y2: mW | AA2: second | AB2: second | AC2: second | AD2: second
A3: source | B3: brain | C3: WB | E3: brain | F3: wb | G3: brain | J3: WB | M3: brain | O3: WB | Q3: front_of_face | R3: brain | S3: WB | T3: brain | U3: WB | V3: wifi | W3: wifi2 | X3: wifi5 | Y3: wifi2 | Z3: wifi5
A4: variable | G4: total | H4: wifi2 | I4: wifi5 | J4: total | K4: wifi2 | L4: wifi5 | M4: wifi2 | N4: wifi5 | O4: wifi2 | P4: wifi5 | AA4: browsing | AB4: audio | AC4: video | AD4: upload | AE4: brwosing | AF4: voice | AG4: video | AH4: upload
A5: Summary | B5: =D5*E5 -> 7.8700348 | C5: =D5*F5 -> 7.5665043 | D5: =SUM(AA5:AD5) -> 1382.867 | E5: =G5 -> 0.0056911004 | F5: =J5 -> 0.0054716068 | G5: =W5*H5+X5*I5 -> 0.0056911004 | H5: =M5*Y5 -> 0.0078632934 | I5: =N5*Z5 -> 0.0026914053 | J5: =W5*K5+X5*L5 -> 0.0054716068 | K5: =O5*Y5 -> 0.0060626776 | L5: =P5*Z5 -> 0.0046553661 | M5: =MobileData!P80*Q5 -> 0.0011194632 | N5: =MobileData!P81*Q5 -> 0.00032007162 | O5: =MobileData!S80*Q5 -> 0.00086311725 | P5: =MobileData!S81*Q5 -> 0.00055363292 | Q5: 1 | R5: =MobileCall!BK5 -> 0.0011194632 | S5: =MobileCall!BQ5 -> 0.00086311725 | T5: =MobileCall!BW5 -> 0.00032007162 | U5: =MobileCall!CC5 -> 0.00055363292 | V5: 1 | W5: =MobileCall!DB5 -> 0.58 | X5: =MobileCall!DC5 -> 0.42 | Y5: =(AE5*MobileData!BP5*MobileCall!FB5+AF5*MobileData!BQ5*MobileCall!FB5+AG5*MobileData!BR5*MobileCall!FB5+AH5*MobileData!BS5*MobileCall!FB5) -> 7.0241646 | Z5: =(AE5*MobileData!BT5*MobileCall!FC5+AF5*MobileData!BU5*MobileCall!FC5+AG5*MobileData!BV5*MobileCall!FC5+AH5*MobileData!BW5*MobileCall!FC5) -> 8.4087595 | AA5: =[1]Sheet1!$B$21 -> 312.74362 | AB5: =[1]Sheet1!$B$22 -> 457.79028 | AC5: =[1]Sheet1!$B$23 -> 612.33308 | AD5: 0 | AE5: =AA5/D5 -> 0.22615597 | AF5: =AB5/D5 -> 0.33104433 | AG5: =AC5/D5 -> 0.4427997 | AH5: =AD5/D5 -> 0
A6: user_inputs
A7: single data | D7: 29.6 | AE7: van Wel L, Liorni I, Huss A, Thielens A, Wiart J, Joseph W, et al. Radio-frequency electromagnetic field exposure and contribution of sources in the general population: an organ-specific integrative exposure assessment. J Expo Sci Environ Epidemiol. 2021;31(6):999-1007.
D8: 24.3 | AE8: Birks LE, van Wel L, Liorni I, Pierotti L, Guxens M, Huss A, et al. Radiofrequency electromagnetic fields from mobile communication: Description of modeled dose in brain regions and the body in European children and adolescents. Environmental research. 2021;193:110505
AC9: wifi_tech is expert opinion | AE9: expert opinion
Y10: just to remind you that you make connection between this wifi and mobile dat awifi | Z10: just to remind you that you make connection between this wifi and mobile dat awifi
AC11: if user changes the time durations for low or high, the total duration (D5) will be sum up of these two low and high durations, otherwise we keep the defulat value
B15: D5*E5*G5 | C15: D5*G5*F5
I75: wb
G76: belly | H76: front of face | I76: far | J76: belly | K76: fof
G77: =MobileCall!FK29*EN5+MobileCall!FM29*EP5 -> 0 | H77: =MobileCall!AR42 -> 0 | I77: 0 | J77: =MobileCall!FK29*EW5+MobileCall!FM29*EY5 -> 0 | K77: =MobileCall!T37 -> 0.0012757832
G78: =MobileCall!FI30*EL5+MobileCall!FJ30*EM5+MobileCall!FK30*EN5+MobileCall!FL30*EO5+MobileCall!FM30*EP5+MobileCall!FN30*ER5 -> 0 | H78: =MobileCall!AR43 -> 0 | I78: 0 | J78: =MobileCall!FI30*EU5+MobileCall!FJ30*EV5+MobileCall!FK30*EW5+MobileCall!FL30*EX5+MobileCall!FM30*EY5+MobileCall!FN30*FA5 -> 0 | K78: =MobileCall!T38 -> 0.001200065
G79: =ES5 -> 0 | H79: =MobileCall!AR44 -> 0 | I79: 0 | J79: =FB5 -> 0 | K79: =MobileCall!T39 -> 0.00022368506
G80: =EQ5 -> 0 | H80: =MobileCall!#REF! -> #REF! | I80: 0 | J80: =EZ5 -> 0 | K80: =MobileCall!BJ5 -> 0.00037289035
G81: =ET5 -> 0 | H81: =MobileCall!BP5 -> 0.0023780397 | I81: 0 | J81: =FC5 -> 0 | K81: =MobileCall!BV5 -> 0.00010658385

Sheet Farfield
B1: Total_dose_ff | D1: Duration | E1: mSAR | G1: Agregated_nSAR | I1: Agregated_exposure | J1: Duration_env | N1: proportion_env | R1: Urbanicity | AD1: exposure | AN1: BTS_close | AR1: BTS_close | AU1: frequency contribution | BE1: SAR
B2: mJ/kg/day | C2: mJ/kg/day | D2: second | E2: (W*mW)/(kg*W) | G2: (W/kg)/(W/m2) | I2: mW/m2 | J2: second | R2: urban_home | T2: urban_work | V2: suburban_home | X2: suburban_work | Z2: rural_home | AB2: rural_work | AD2: mW/m2 | AN2: home | AP2: work | AR2: mW/m2 | AU2: proportion | BE2: (W/kg)/(W/m2)
A3: info/default | B3: brain | C3: WB | E3: Brain | F3: WB | G3: Brain | H3: WB | J3: home | K3: outdoor | L3: work | M3: traveling | N3: home | O3: outdoor | P3: work | Q3: traveling | S3: default | U3: default | V3: default | X3: default | AA3: default | AC3: default | AD3: urban_home | AE3: urban_outdoor | AF3: urban_work | AG3: suburban_home | AH3: suburban_outdoor | AI3: suburban_work | AJ3: rural_home | AK3: rural_outdoor | AL3: rural_work | AM3: traveling | AO3: default | AQ3: default | AU3: <700 | AV3: 700 | AW3: 800 | AX3: 900 | AY3: 1800 | AZ3: 2100 | BA3: 2450 | BB3: 2600 | BC3: 3500 | BD3: 5000 | BE3: brain | BO3: WB | BY3: Reference | BZ3: Remarks
A4: variable | R4: yes | S4: no | T4: yes | U4: no | V4: yes | W4: no | X4: yes | Y4: no | Z4: yes | AA4: no | AB4: yes | AC4: no | AN4: yes | AO4: No | AP4: yes | AQ4: No | AR4: <50 m | AS4: 50-250 m | AT4: 250-500 | BE4: <700 | BF4: 700 | BG4: 800 | BH4: 900 | BI4: 1800 | BJ4: 2100 | BK4: 2450 | BL4: 2600 | BM4: 3500 | BN4: 5000 | BO4: <700 | BP4: 700 | BQ4: 800 | BR4: 900 | BS4: 1800 | BT4: 2100 | BU4: 2450 | BV4: 2600 | BW4: 3500 | BX4: 5000
A5: Summary | B5: =D5*E5 -> 162.57839 | C5: =D5*F5 -> 136.02053 | D5: =SUM(J5:M5) -> 86400 | E5: =G5*I5 -> 0.0018816943 | F5: =H5*I5 -> 0.0015743117 | G5: =AU5*BE5+AV5*BF5+AW5*BG5+AX5*BH5+AY5*BI5+AZ5*BJ5+BA5*BK5+BB5*BL5+BC5*BM5+BD5*BN5 -> 0.0054913152 | H5: =AU5*BE5+AV5*BP5+AW5*BQ5+AX5*BR5+AY5*BS5+AZ5*BT5+BA5*BU5+BB5*BV5+BC5*BW5+BD5*BX5 -> 0.004594286 | I5: =(N5*S5*AD5)+(N5*AA5*AJ5)+(N5*V5*AG5)+(O5*S5*AE5)+(O5*V5*AH5)+(O5*AA5*AL5)+(P5*U5*AF5)+(P5*X5*AI5)+(P5*AC5*AK5)+(Q5*AM5) -> 0.34266733 | J5: =(24*60*60)-K5-L5-M5 -> 59349.949 | K5: =K8*60*60 -> 7200 | L5: =L9*60*60 -> 18000 | M5: =[1]Sheet1!$B$3 -> 1850.0512 | N5: =J5/D5 -> 0.6869207 | O5: =K5/D5 -> 0.083333333 | P5: =L5/D5 -> 0.20833333 | Q5: =M5/D5 -> 0.021412629 | R5: 1 | S5: 0 | T5: 1 | U5: 0 | V5: 1 | W5: 0 | X5: 1 | Y5: 0 | Z5: 1 | AA5: 0 | AB5: 1 | AC5: 0 | AD5: 0.44845925 | AE5: 1.2933706 | AF5: 0.63857307 | AG5: 0.26831998 | AH5: 0.77384327 | AI5: 0.38316991 | AJ5: 0.08818071 | AK5: 0.25431594 | AL5: 0.12776674 | AM5: 0.6556309 | AN5: 1 | AO5: 0 | AP5: 1 | AQ5: 0 | AR5: =((SQRT(AR18^2+AR19^2+AR14^2))^2/377)*1000 -> 2.0541114 | AS5: =((SQRT(AS15^2+AS14^2+AS20^2))^2/377)*1000 -> 1.1554377 | AT5: =((SQRT(AT16^2+AT14^2+AT20^2))^2/377)*1000 -> 0.66312997 | AU5: 0.08 | AV5: 0.04 | AW5: 0.15 | AX5: 0.17 | AY5: 0.23 | AZ5: 0.15 | BA5: 0.02 | BB5: 0.07 | BC5: 0.07 | BD5: 0.02 | BE5: =[2]Sheet1!$M$2 -> 0.0063492632 | BF5: =[2]Sheet1!$L$5 -> 0.008410606 | BG5: =[2]Sheet1!$L$6 -> 0.0086691144 | BH5: =[2]Sheet1!$L$7 -> 0.0087110652 | BI5: =[2]Sheet1!$L$8 -> 0.0044534377 | BJ5: =[2]Sheet1!$L$9 -> 0.003408901 | BK5: =[2]Sheet1!$L$10 -> 0.0026181892 | BL5: =[2]Sheet1!$L$11 -> 0.0023785686 | BM5: =[2]Sheet1!$L$12 -> 0.0014298366 | BN5: =[2]Sheet1!$L$13 -> 0.0005561826 | BO5: =[3]Sheet1!$M$2 -> 0.0068286364 | BP5: =[3]Sheet1!$L$5 -> 0.0056272613 | BQ5: =[3]Sheet1!$L$6 -> 0.0054880185 | BR5: =[3]Sheet1!$L$7 -> 0.0053320621 | BS5: =[3]Sheet1!$L$8 -> 0.0042387458 | BT5: =[3]Sheet1!$L$9 -> 0.0039545999 | BU5: =[3]Sheet1!$L$10 -> 0.0035596547 | BV5: =[3]Sheet1!$L$11 -> 0.0034417505 | BW5: =[3]Sheet1!$L$12 -> 0.0029049748 | BX5: =[3]Sheet1!$L$13 -> 0.0024017885
A6: user_inputs
A7: single dat | J7: 990 | BY7: expert opinion
K8: =120/60 -> 2 | BY8: An overview analysis of the time people spend outdoors (for time outdoor | BZ8: (0.28 of year is weekend*2.38 h spend outdoor)+(5.5*0.08 of year is weekend)+(0.62*1.43)
B9: new calculations | C9: new calculations | L9: =300/60 -> 5 | AT9: Adriana_2023_EU | AU9: 0.08 | AV9: 0.04 | AW9: 0.15 | AX9: 0.17 | AY9: 0.23 | AZ9: 0.15 | BA9: 0.02 | BB9: 0.07 | BC9: 0.07 | BD9: 0.02 | BY9: Eurostat: official website of the European Union; https://ec.europa.eu/eurostat/statistics-explained/index.php?oldid=473885#:~:text=In%20the%20EU%2C%20in%202022%2C,actual%20and%20usual%20work%20hours | BZ9: 365 d/y, 30 d holiday, 104 d weekends; [calculation: (365-104-30)*8)/365= 5 h/d]
M10: 30 | BY10: Eurostat. Majority commuted less than 30 minutes in 2019. European Commission; 2020
BY11: Eurostat. Majority commuted less than 30 minutes in 2019. European Commission; 2021
